Workbook

Sheet Mapper Ops
A1: JAVA 파일 | B1: MAPPER 파일 | C1: Mapper ID | D1: TABLE명 | E1: CRUD 구분 | F1: 배치코드 | G1: 배치작업
A2: Trbt001m | B2: Trbt001m.xml | C2: deleteIfSwapdb | D2: IF_SWAPDB_FWD_M_TR_INFO | E2: D | F2: 1 | G2: =VLOOKUP($F2,'배치코드-작업'!$A$2:$B$41,2,FALSE) -> SPEC 데이터 인터페이스
A3: Trbt001m | B3: Trbt001m.xml | C3: insertIfSwapdb | D3: IF_SWAPDB_FWD_M_TR_INFO | E3: C | F3: 1 | G3: =VLOOKUP($F3,'배치코드-작업'!$A$2:$B$41,2,FALSE) -> SPEC 데이터 인터페이스
A4: Trbt001m | B4: Trbt001m.xml | C4: selectIfSwapdbList | D4: SWAPDB_FWD_M_TR_Info | E4: R | F4: 1 | G4: =VLOOKUP($F4,'배치코드-작업'!$A$2:$B$41,2,FALSE) -> SPEC 데이터 인터페이스
A5: Trbt010m | B5: Trbt010m.xml | C5: fnGetSampleData001 | D5: DUAL | E5: R | F5: 10 | G5: =VLOOKUP($F5,'배치코드-작업'!$A$2:$B$41,2,FALSE) -> 시장데이터 수신
A6: Trbt020m | B6: Trbt020m.xml | C6: fnUpdateSampleData002 | D6: TD_DMDATALOAD | E6: U | F6: 20 | G6: =VLOOKUP($F6,'배치코드-작업'!$A$2:$B$41,2,FALSE) -> 수신데이터검증
A7: Trbt020m | B7: Trbt020m.xml | C7: deleteDataCheckResult | D7: TD_DMDATACHECKRESULT | E7: D | F7: 20 | G7: =VLOOKUP($F7,'배치코드-작업'!$A$2:$B$41,2,FALSE) -> 수신데이터검증
A8: Trbt020m | B8: Trbt020m.xml | C8: selectDataCheckInfoList | D8: TC_DMDATACHECKINFO | E8: R | F8: 20 | G8: =VLOOKUP($F8,'배치코드-작업'!$A$2:$B$41,2,FALSE) -> 수신데이터검증
A9: Trbt020m | B9: Trbt020m.xml | C9: selectDataCheckResult | D9: ${sqlScript} | E9: R | F9: 20 | G9: =VLOOKUP($F9,'배치코드-작업'!$A$2:$B$41,2,FALSE) -> 수신데이터검증
A10: Trbt020m | B10: Trbt020m.xml | C10: insertDataCheckResult | D10: TD_DMDATACHECKRESULT | E10: C | F10: 20 | G10: =VLOOKUP($F10,'배치코드-작업'!$A$2:$B$41,2,FALSE) -> 수신데이터검증
A11: Trbt020m | B11: Trbt020m.xml | D11: TC_DMDATACHECKINFO | E11: R | F11: 20 | G11: =VLOOKUP($F11,'배치코드-작업'!$A$2:$B$41,2,FALSE) -> 수신데이터검증
A12: Trbt030m | B12: Trbt030m.xml | C12: fnGetSampleData002 | D12: TD_DMDATALOAD | E12: R | F12: 30 | G12: =VLOOKUP($F12,'배치코드-작업'!$A$2:$B$41,2,FALSE) -> 0
A13: Trbt030m | B13: Trbt030m.xml | C13: fnDeleteSampleData002 | D13: TD_DMDATALOAD | E13: D | F13: 30 | G13: =VLOOKUP($F13,'배치코드-작업'!$A$2:$B$41,2,FALSE) -> 0
A14: Trbt030m | B14: Trbt030m.xml | C14: fnInsertSampleData002 | D14: TD_DMDATALOAD | E14: U | F14: 30 | G14: =VLOOKUP($F14,'배치코드-작업'!$A$2:$B$41,2,FALSE) -> 0
A15: Trbt030m | B15: Trbt030m.xml | C15: getSysDate | E15: R | F15: 30 | G15: =VLOOKUP($F15,'배치코드-작업'!$A$2:$B$41,2,FALSE) -> 0
A16: Trbt030m | B16: Trbt030m.xml | C16: selectSmsDataList | D16: dbo.SUREData_Log | E16: R | F16: 30 | G16: =VLOOKUP($F16,'배치코드-작업'!$A$2:$B$41,2,FALSE) -> 0
A17: Trbt030m | B17: Trbt030m.xml | C17: deleteIfFxFwd | D17: IF_FXFWD | E17: D | F17: 30 | G17: =VLOOKUP($F17,'배치코드-작업'!$A$2:$B$41,2,FALSE) -> 0
A18: Trbt030m | B18: Trbt030m.xml | C18: insertIfFxFwd | D18: IF_FXFWD | E18: C | F18: 30 | G18: =VLOOKUP($F18,'배치코드-작업'!$A$2:$B$41,2,FALSE) -> 0
A19: Trbt030m | B19: Trbt030m.xml | C19: selectIfFxFwdList | D19: #TEMP_FXFWD SWAPDB_FXForward_Info S1 INNER JOIN SWAPDB_FXForward_Delivery S2 ON S1.FXDealID = S2.FXDealID LEFT OUTER JOIN RCV_OUTSIDE_HDL_H_SAMU_SWAP S3 SWAPDB_FXForward_Info S1 INNER JOIN SENDDB_SND_M_DuplicationCode S2 ON S1.FXDealID = S2.ProductID AND S1.PartyCode = S2.PartyCode LEFT OUTER JOIN RCV_OUTSIDE_HDL_H_SAMU_SWAP S3 | E19: R | F19: 30 | G19: =VLOOKUP($F19,'배치코드-작업'!$A$2:$B$41,2,FALSE) -> 0
A20: Trbt030m | B20: Trbt030m.xml | D20: #TEMP_PACKAGE_INFO #TEMP_FXFWD S1 INNER JOIN SWAPDB_FWD_M_TR_info_Backup S2 SWAPDB_FXForward_Info A INNER JOIN #TEMP_FXFWD B ON A.PartyCode = B.PartyCode AND A.FXDealID = B.FXDealID LEFT OUTER JOIN SWAPDB_FWD_M_TR_info_Backup | E20: R | F20: 30 | G20: =VLOOKUP($F20,'배치코드-작업'!$A$2:$B$41,2,FALSE) -> 0
A21: Trbt030m | B21: Trbt030m.xml | C21: selectIfFxFwdVlnList | D21: #TEMP_FXFWD SWAPDB_FXForward_Info S1 INNER JOIN SWAPDB_FXForward_Delivery S2 SWAPDB_FXForward_Info S1 INNER JOIN SENDDB_SND_M_DuplicationCode S2 SWAPDB_FXForward_Info S1 INNER JOIN SWAPDB_FXForward_Delivery S2 LEFT OUTER JOIN RCV_OUTSIDE_HDL_H_SAMU_SWAP S3 SWAPDB_FXForward_Info S1 INNER JOIN SENDDB_SND_M_DuplicationCode S2 LEFT OUTER JOIN RCV_OUTSIDE_HDL_H_SAMU_SWAP S3 | E21: R | F21: 30 | G21: =VLOOKUP($F21,'배치코드-작업'!$A$2:$B$41,2,FALSE) -> 0
A22: Trbt030m | B22: Trbt030m.xml | D22: #TEMP_PACKAGE_INFO #TEMP_FXFWD S1 INNER JOIN SWAPDB_FWD_M_TR_info_Backup S2 SWAPDB_FXForward_Info A INNER JOIN #TEMP_FXFWD B LEFT OUTER JOIN SWAPDB_FWD_M_TR_info_Backup LEFT OUTER JOIN SWAPDB_FXForward_Value | E22: R | F22: 30 | G22: =VLOOKUP($F22,'배치코드-작업'!$A$2:$B$41,2,FALSE) -> 0
A23: Trbt030m | B23: Trbt030m.xml | C23: deleteIfFxFwdVln | D23: IF_FX_VLN | E23: D | F23: 30 | G23: =VLOOKUP($F23,'배치코드-작업'!$A$2:$B$41,2,FALSE) -> 0
A24: Trbt030m | B24: Trbt030m.xml | C24: insertIfFxFwdVln | D24: IF_FX_VLN | E24: C | F24: 30 | G24: =VLOOKUP($F24,'배치코드-작업'!$A$2:$B$41,2,FALSE) -> 0
A25: Trbt040m | B25: Trbt040m.xml | C25: fnGetFieldData | D25: TD_DMDATALOAD | E25: R | F25: 40 | G25: =VLOOKUP($F25,'배치코드-작업'!$A$2:$B$41,2,FALSE) -> TEST
A26: Trbt040m | B26: Trbt040m.xml | C26: fnDeletePrevData | D26: TD_DMDATALOAD | E26: D | F26: 40 | G26: =VLOOKUP($F26,'배치코드-작업'!$A$2:$B$41,2,FALSE) -> TEST
A27: Trbt040m | B27: Trbt040m.xml | C27: fnInsertDynamic | D27: TD_DMDATALOAD | E27: C | F27: 40 | G27: =VLOOKUP($F27,'배치코드-작업'!$A$2:$B$41,2,FALSE) -> TEST
A28: Trbt049m | B28: Trbt049m.xml | C28: updateBoGoodSrc100100 | D28: ${boGoodSrcTableName} | E28: R | F28: 49 | G28: =VLOOKUP($F28,'배치코드-작업'!$A$2:$B$41,2,FALSE) -> 고객사 상품 CUST작업
A29: Trbt049m | B29: Trbt049m.xml | C29: updateBoGoodSrc200200 | D29: ${boGoodSrcTableName} | E29: R | F29: 49 | G29: =VLOOKUP($F29,'배치코드-작업'!$A$2:$B$41,2,FALSE) -> 고객사 상품 CUST작업
A30: Trbt049m | B30: Trbt049m.xml | C30: updateBoGoodSrc301300 | D30: ${boGoodSrcTableName} | E30: R | F30: 49 | G30: =VLOOKUP($F30,'배치코드-작업'!$A$2:$B$41,2,FALSE) -> 고객사 상품 CUST작업
A31: Trbt050m | B31: Trbt050m.xml | C31: selectGoodColList | D31: TC_CMTABLEDATEGRPJOBLIST | E31: R | F31: 50 | G31: =VLOOKUP($F31,'배치코드-작업'!$A$2:$B$41,2,FALSE) -> 매매기초정보생성
A32: Trbt050m | B32: Trbt050m.xml | C32: selectGoodColListIncludeKey | D32: TC_CMTABLEDATEGRPJOBLIST | E32: R | F32: 50 | G32: =VLOOKUP($F32,'배치코드-작업'!$A$2:$B$41,2,FALSE) -> 매매기초정보생성
A33: Trbt050m | B33: Trbt050m.xml | C33: deletePrevBoGoodData | D33: ${boGoodTableName} | E33: D | F33: 50 | G33: =VLOOKUP($F33,'배치코드-작업'!$A$2:$B$41,2,FALSE) -> 매매기초정보생성
A34: Trbt050m | B34: Trbt050m.xml | C34: selectMaxInsertSeq | D34: ${boGoodSrcTableName} | E34: R | F34: 50 | G34: =VLOOKUP($F34,'배치코드-작업'!$A$2:$B$41,2,FALSE) -> 매매기초정보생성
A35: Trbt050m | B35: Trbt050m.xml | C35: insertBoGoodFromSrc | D35: ${boGoodTableName} | E35: C | F35: 50 | G35: =VLOOKUP($F35,'배치코드-작업'!$A$2:$B$41,2,FALSE) -> 매매기초정보생성
A36: Trbt050m | B36: Trbt050m.xml | D36: ${boGoodSrcTableName} | E36: R(INSERT) | F36: 50 | G36: =VLOOKUP($F36,'배치코드-작업'!$A$2:$B$41,2,FALSE) -> 매매기초정보생성
A37: Trbt050m | B37: Trbt050m.xml | C37: mergeBoGoodFromSrc | D37: ${boGoodTableName} | E37: U(MERGE) | F37: 50 | G37: =VLOOKUP($F37,'배치코드-작업'!$A$2:$B$41,2,FALSE) -> 매매기초정보생성
A38: Trbt050m | B38: Trbt050m.xml | D38: ${boGoodSrcTableName} | E38: U(MERGE) | F38: 50 | G38: =VLOOKUP($F38,'배치코드-작업'!$A$2:$B$41,2,FALSE) -> 매매기초정보생성
A39: Trbt050m | B39: Trbt050m.xml | C39: updateBoGoodIn | D39: ${boGoodInTableName} | E39: U | F39: 50 | G39: =VLOOKUP($F39,'배치코드-작업'!$A$2:$B$41,2,FALSE) -> 매매기초정보생성
A40: Trbt050m | B40: Trbt050m.xml | C40: mergeBoGoodFromIn | D40: ${boGoodTableName} | E40: U(MERGE) | F40: 50 | G40: =VLOOKUP($F40,'배치코드-작업'!$A$2:$B$41,2,FALSE) -> 매매기초정보생성
...

Sheet 배치코드-작업
A1: 배치코드 | B1: 배치작업
B2: NULL
A3: 1 | B3: SPEC 데이터 인터페이스
A4: 10 | B4: 시장데이터 수신
A5: 20 | B5: 수신데이터검증
A6: 30
A7: 40 | B7: TEST
A8: 49 | B8: 고객사 상품 CUST작업
A9: 50 | B9: 매매기초정보생성
A10: 51 | B10: 매매정보생성
A11: 52 | B11: 가치평가정보생성
A12: 53 | B12: 담보정보생성
A13: 54 | B13: 기타정보생성
A14: 60 | B14: 거래기초데이터생성
A15: 65 | B15: 매매관리데이터생성
A16: 66 | B16: 가치평가누락데이터생성
A17: 70 | B17: 가치평가관리데이터생성
A18: 74 | B18: 담보평가누락데이터생성
... A41: 900 | B41: 메일발송
